2025-04-11 17:44:47,446 INFO    MainThread:17608 [wandb_setup.py:_flush():67] Current SDK version is 0.19.7
2025-04-11 17:44:47,447 INFO    MainThread:17608 [wandb_setup.py:_flush():67] Configure stats pid to 17608
2025-04-11 17:44:47,447 INFO    MainThread:17608 [wandb_setup.py:_flush():67] Loading settings from C:\Users\Bryan\.config\wandb\settings
2025-04-11 17:44:47,447 INFO    MainThread:17608 [wandb_setup.py:_flush():67] Loading settings from c:\Users\Bryan\Desktop\ResearchAI\wandb\settings
2025-04-11 17:44:47,447 INFO    MainThread:17608 [wandb_setup.py:_flush():67] Loading settings from environment variables
2025-04-11 17:44:47,447 INFO    MainThread:17608 [wandb_init.py:setup_run_log_directory():647] Logging user logs to c:\Users\Bryan\Desktop\ResearchAI\wandb\run-20250411_174447-kw68glkk\logs\debug.log
2025-04-11 17:44:47,447 INFO    MainThread:17608 [wandb_init.py:setup_run_log_directory():648] Logging internal logs to c:\Users\Bryan\Desktop\ResearchAI\wandb\run-20250411_174447-kw68glkk\logs\debug-internal.log
2025-04-11 17:44:47,447 INFO    MainThread:17608 [wandb_init.py:monkeypatch_ipython():599] configuring jupyter hooks <wandb.sdk.wandb_init._WandbInit object at 0x0000029D3772F140>
2025-04-11 17:44:47,447 INFO    MainThread:17608 [wandb_init.py:init():761] calling init triggers
2025-04-11 17:44:47,447 INFO    MainThread:17608 [wandb_init.py:init():766] wandb.init called with sweep_config: {}
config: {'backbone_type': 'dinov2', 'model_size': 'small', 'embedding_dim': 384, 'projection_dim': 256, 'dataset_name': 'crop14_balance', 'num_classes': 14, 'num_diet_classes': 10, 'input_size': 512, 'is_rgb': True, 'limit_data': 1000, 'num_epoch': 30, 'batch_size': 20, 'lr': 0.0005, 'weight_decay': 0.05, 'da_strength': 1, 'label_smoothing': 0.3, 'is_diet_active': True, '_wandb': {}}
2025-04-11 17:44:47,447 INFO    MainThread:17608 [wandb_init.py:init():784] starting backend
2025-04-11 17:44:47,447 INFO    MainThread:17608 [wandb_init.py:init():788] sending inform_init request
2025-04-11 17:44:47,473 INFO    MainThread:17608 [wandb_init.py:init():803] backend started and connected
2025-04-11 17:44:47,477 INFO    MainThread:17608 [wandb_run.py:_label_probe_notebook():1204] probe notebook
2025-04-11 17:44:47,478 INFO    MainThread:17608 [wandb_run.py:_label_probe_notebook():1214] Unable to probe notebook: 'NoneType' object has no attribute 'get'
2025-04-11 17:44:47,479 INFO    MainThread:17608 [wandb_init.py:init():896] updated telemetry
2025-04-11 17:44:47,480 INFO    MainThread:17608 [wandb_init.py:init():920] communicating run to backend with 90.0 second timeout
2025-04-11 17:44:47,745 INFO    MainThread:17608 [wandb_init.py:init():995] starting run threads in backend
2025-04-11 17:44:47,956 INFO    MainThread:17608 [wandb_run.py:_console_start():2377] atexit reg
2025-04-11 17:44:47,956 INFO    MainThread:17608 [wandb_run.py:_redirect():2227] redirect: wrap_raw
2025-04-11 17:44:47,957 INFO    MainThread:17608 [wandb_run.py:_redirect():2292] Wrapping output streams.
2025-04-11 17:44:47,957 INFO    MainThread:17608 [wandb_run.py:_redirect():2317] Redirects installed.
2025-04-11 17:44:47,959 INFO    MainThread:17608 [wandb_init.py:init():1037] run started, returning control to user process
2025-04-11 20:03:48,952 INFO    MainThread:17608 [jupyter.py:save_ipynb():386] not saving jupyter notebook
2025-04-11 20:03:48,953 INFO    MainThread:17608 [wandb_init.py:_pause_backend():564] pausing backend
2025-04-11 20:03:58,721 WARNING MsgRouterThr:17608 [router.py:message_loop():77] message_loop has been closed
Traceback (most recent call last):
  File "c:\Users\Bryan\miniconda3\envs\research\Lib\site-packages\wandb\sdk\lib\sock_client.py", line 258, in _read_packet_bytes
    data = self._sock.recv(self._bufsize)
           ^^^^^^^^^^^^^^^^^^^^^^^^^^^^^^
ConnectionResetError: [WinError 10054] An existing connection was forcibly closed by the remote host

The above exception was the direct cause of the following exception:

Traceback (most recent call last):
  File "c:\Users\Bryan\miniconda3\envs\research\Lib\site-packages\wandb\sdk\interface\router_sock.py", line 28, in _read_message
    resp = self._sock_client.read_server_response(timeout=1)
           ^^^^^^^^^^^^^^^^^^^^^^^^^^^^^^^^^^^^^^^^^^^^^^^^^
  File "c:\Users\Bryan\miniconda3\envs\research\Lib\site-packages\wandb\sdk\lib\sock_client.py", line 285, in read_server_response
    data = self._read_packet_bytes(timeout=timeout)
           ^^^^^^^^^^^^^^^^^^^^^^^^^^^^^^^^^^^^^^^^
  File "c:\Users\Bryan\miniconda3\envs\research\Lib\site-packages\wandb\sdk\lib\sock_client.py", line 262, in _read_packet_bytes
    raise SockClientClosedError from e
wandb.sdk.lib.sock_client.SockClientClosedError

The above exception was the direct cause of the following exception:

Traceback (most recent call last):
  File "c:\Users\Bryan\miniconda3\envs\research\Lib\site-packages\wandb\sdk\interface\router.py", line 70, in message_loop
    msg = self._read_message()
          ^^^^^^^^^^^^^^^^^^^^
  File "c:\Users\Bryan\miniconda3\envs\research\Lib\site-packages\wandb\sdk\interface\router_sock.py", line 30, in _read_message
    raise MessageRouterClosedError from e
wandb.sdk.interface.router.MessageRouterClosedError
2025-04-11 20:03:58,726 INFO    MsgRouterThr:17608 [mailbox.py:close():115] Closing mailbox, abandoning 2 handles.
